<?xml version="1.0" ?>
<sdf version="1.8">

  <model name="next">

    <pose>0 0 0 0 0 0</pose>
    <link name="base_footprint"/>
    <joint name="base_joint" type="fixed">
      <parent>base_footprint</parent>
      <child>base_link</child>
      <pose>0 0 0 0 0 0</pose>
    </joint>

    <link name="base_link">
      <pose>0 0 0.03425 0 0 0</pose>
      <inertial>
        <pose>-0.04909 -0.000455 0.037522 0 0 0</pose>
        <inertia>
          <ixx>0.00515664638106363</ixx>
          <ixy>-6.45642369348053e-05</ixy>
          <ixz>-0.000213882833343026</ixz>
          <iyy>0.00733996252095999</iyy>
          <iyz>-1.46081559898697e-06</iyz>
          <izz>0.0114101062823264</izz>
        </inertia>
        <mass>1.6</mass>
      </inertial>
      <collision name="base_collision">
        <pose>0 0 0 0 0 0</pose>
        <geometry>
          <mesh>
            <uri>meshes/next_urdf.stl</uri>
            <scale>0.001 0.001 0.001</scale>
          </mesh>
        </geometry>
      </collision>
      <visual name="base_visual">
        <pose>0 0 0 0 0 0</pose>
        <geometry>
          <mesh>
            <uri>meshes/next_urdf.dae</uri>
            <scale>1 1 1</scale>
          </mesh>
        </geometry>
      </visual>
      <gravity>1</gravity>
      <kinematic>0</kinematic>
    </link>

    <joint name="wheel_left_joint" type="revolute">
      <parent>base_link</parent>
      <child>wheel_left_link</child>
      <axis>
        <xyz>0 0 1</xyz>
        <limit>
            <lower>-1.79769e+308</lower>
            <upper>1.79769e+308</upper>
        </limit>
      </axis>
    </joint>
    <link name="wheel_left_link">
      <pose>0 0.087 0.03425 -1.57 0 0</pose>
      <inertial>
        <pose>0 0 0 0 0 0</pose>
        <inertia>
          <ixx>2.29346485819975e-5</ixx>
          <ixy>0</ixy>
          <ixz>0</ixz>
          <iyy>4.19370640001351e-5</iyy>
          <iyz>0</iyz>
          <izz>2.29346485819975e-5</izz>
        </inertia>
        <mass>0.06</mass>
      </inertial>
      <collision name="wheel_left_collision">
        <pose>0 0 0 0 0 0</pose>
        <geometry>
          <cylinder>
            <radius>0.03475</radius>
            <length>0.0225</length>
          </cylinder>
        </geometry>
        <surface>
            <friction>
                <ode>
                    <mu>0.7</mu>
                    <mu2>150</mu2>
                    <fdir1>0 1 0</fdir1>
                </ode>
            </friction>
            <contact>
              <ode>
                <soft_cfm>0</soft_cfm>
                <soft_erp>0.2</soft_erp>
                <kp>5e+5</kp>
                <kd>1</kd>
                <max_vel>0.01</max_vel>
                <min_depth>0.001</min_depth>
              </ode>
            </contact>
            <max_contacts>20</max_contacts>
        </surface>
      </collision>
      <visual name="wheel_left_visual">
        <pose>0 0 0 0 0 0</pose>
        <geometry>
          <mesh>
            <uri>meshes/wheel_left.dae</uri>
            <scale>1 1 1</scale>
          </mesh>
        </geometry>
      </visual>
      <gravity>1</gravity>
      <kinematic>0</kinematic>
    </link>

    <joint name="wheel_right_joint" type="revolute">
      <parent>base_link</parent>
      <child>wheel_right_link</child>
      <axis>
        <xyz>0 0 1</xyz>
        <limit>
            <lower>-1.79769e+308</lower>
            <upper>1.79769e+308</upper>
        </limit>
      </axis>
    </joint>
    <link name="wheel_right_link">
      <pose>0 -0.087 0.03425 -1.57 0 0</pose>
      <inertial>
        <pose>0 0 0 0 0 0</pose>
        <inertia>
          <ixx>2.29346485819975e-5</ixx>
          <ixy>0</ixy>
          <ixz>0</ixz>
          <iyy>4.19370640001351e-5</iyy>
          <iyz>0</iyz>
          <izz>2.29346485819975e-5</izz>
        </inertia>
        <mass>0.06</mass>
      </inertial>
      <collision name="wheel_right_collision">
        <pose>0 0 0 0 0 0</pose>
        <geometry>
          <cylinder>
            <radius>0.03475</radius>
            <length>0.0225</length>
          </cylinder>
        </geometry>
        <surface>
            <friction>
                <ode>
                    <mu>0.7</mu>
                    <mu2>150</mu2>
                    <fdir1>0 1 0</fdir1>
                </ode>
            </friction>
            <contact>
              <ode>
                <soft_cfm>0</soft_cfm>
                <soft_erp>0.2</soft_erp>
                <kp>5e+5</kp>
                <kd>1</kd>
                <max_vel>0.01</max_vel>
                <min_depth>0.001</min_depth>
              </ode>
            </contact>
        </surface>
        <max_contacts>20</max_contacts>
      </collision>
      <visual name="wheel_right_visual">
        <pose>0 0 0 0 0 0</pose>
        <geometry>
          <mesh>
            <uri>meshes/wheel_right.dae</uri>
            <scale>1 1 1</scale>
          </mesh>
        </geometry>
      </visual>
      <gravity>1</gravity>
      <kinematic>0</kinematic>
    </link>

    <joint name="wheel_steering_joint" type="revolute">
        <parent>base_link</parent>
        <child>wheel_steering_link</child>
        <axis>
           <xyz>0 0 1</xyz>
           <limit>
             <lower>-1.79769e+308</lower>
             <upper>1.79769e+308</upper>
           </limit>
        </axis>
    </joint>

    <link name="wheel_steering_link">
        <pose>-0.1842 0 0.0255 0 0 0</pose>
        <inertial>
            <mass>0.05</mass>
            <inertia>
              <ixx>0.00001</ixx>
              <ixy>0.0</ixy>
              <ixz>0.0</ixz>
              <iyy>0.00001</iyy>
              <iyz>0.0</iyz>
              <izz>0.00001</izz>
            </inertia>
        </inertial>
    </link>

    <joint name="wheel_castor_joint" type="revolute">
      <parent>wheel_steering_link</parent>
      <child>wheel_castor_link</child>
      <axis>
        <xyz>0 1 0</xyz>
        <limit>
          <lower>-1.79769e+308</lower>
          <upper>1.79769e+308</upper>
        </limit>
      </axis>
    </joint>
    <link name="wheel_castor_link">
      <pose>-0.2002 0 0.01275 0 0 0</pose>
      <inertial>
        <mass>0.1</mass>
        <inertia>
          <ixx>0.00001</ixx>
          <ixy>0.0</ixy>
          <ixz>0.0</ixz>
          <iyy>0.00001</iyy>
          <iyz>0.0</iyz>
          <izz>0.00001</izz>
        </inertia>
      </inertial>
      <collision name="collision">
        <pose>0 0 0 0 0 0</pose>
        <geometry>
          <mesh>
            <uri>meshes/vac_wheel.stl</uri>
            <scale>0.001 0.001 0.001</scale>
          </mesh>
        </geometry>
        <surface>
            <friction>
                <ode>
                    <mu>0.7</mu>
                    <mu2>150</mu2>
                    <fdir1>0 1 0</fdir1>
                </ode>
            </friction>
                <contact>
                <ode>
                    <soft_cfm>0</soft_cfm>
                    <soft_erp>0.2</soft_erp>
                    <kp>5e+5</kp>
                    <kd>1</kd>
                    <max_vel>0.01</max_vel>
                    <min_depth>0.001</min_depth>
                </ode>
            </contact>
        </surface>
        <max_contacts>20</max_contacts>
      </collision>
      <visual name="visual">
        <pose>0 0 0 0 0 0</pose>
        <geometry>
          <mesh>
            <uri>meshes/vac_wheel.dae</uri>
            <scale>1 1 1</scale>
          </mesh>
        </geometry>
      </visual>
      <gravity>1</gravity>
      <velocity_decay/>
      <kinematic>0</kinematic>
    </link>

    <joint name="scan_joint" type="fixed">
      <parent>base_link</parent>
      <child>base_scan</child>
      <axis>
        <xyz>0 0 1</xyz>
      </axis>
    </joint>
    <link name="base_scan">
      <pose>-0.1692 0 0.0955 0 0 0</pose>
      <inertial>
        <pose>0 0 -0.010434 0 0 0</pose>
        <inertia>
          <ixx>9.18898124199496e-06</ixx>
          <ixy>4.00061745069111e-13</ixy>
          <ixz>-7.25387613293144e-13</ixz>
          <iyy>9.18898124199496e-06</iyy>
          <iyz>-2.38106235197307e-12</iyz>
          <izz>1.0149520729016e-05</izz>
        </inertia>
        <mass>0.047</mass>
      </inertial>
      <collision name="base_scan_collision">
        <pose>0 0 0 0 0 0</pose>
        <geometry>
          <mesh>
            <uri>meshes/ldlidar.stl</uri>
            <scale>0.001 0.001 0.001</scale>
          </mesh>
        </geometry>
      </collision>
      <visual name="base_scan_visual">
        <pose>0 0 0 0 0 0</pose>
        <geometry>
          <mesh>
            <uri>meshes/ldlidar.dae</uri>
            <scale>1 1 1</scale>
          </mesh>
        </geometry>
      </visual>
      <sensor name='gpu_lidar' type='gpu_lidar'>
          <pose>0 0 0 0 0 0</pose>
          <topic>scan</topic>
          <gz_frame_id>next/base_scan</gz_frame_id>
          <update_rate>10</update_rate>
          <lidar>
            <scan>
              <horizontal>
                <samples>640</samples>
                <resolution>1</resolution>
                <min_angle>-1.396263</min_angle>
                <max_angle>1.396263</max_angle>
              </horizontal>
              <vertical>
                <samples>1</samples>
                <resolution>1</resolution>
                <min_angle>0.0</min_angle>
                <max_angle>0.0</max_angle>
              </vertical>
            </scan>
            <range>
              <min>0.08</min>
              <max>10.0</max>
              <resolution>0.01</resolution>
            </range>
          </lidar>
          <visualize>true</visualize>
      </sensor>
      <gravity>1</gravity>
      <kinematic>0</kinematic>
      <!-- TODO set range-->
      <!-- TODO: then move on to checking inertias -->
      <!-- TODO: imu ENU, ZED, check -->
    </link>

    <joint name="imu_joint" type="fixed">
      <parent>base_link</parent>
      <child>imu_link</child>
    </joint>
    <link name="imu_link">
      <pose>0.0378 0.0 0.08155 0 0 0</pose>
      <inertial>
        <pose>0 0 0 0 0 0</pose>
        <inertia>
          <ixx>7.52133382161458e-07</ixx>
          <ixy>0.0</ixy>
          <ixz>0.0</ixz>
          <iyy>1.33546671549479e-06</iyy>
          <iyz>0.0</iyz>
          <izz>2.08333333333333e-06</izz>
        </inertia>
        <mass>0.01</mass>
      </inertial>
      <collision name='imu_link_collision'>
        <pose>0 0 0 0 0 0</pose>
        <geometry>
          <mesh>
            <uri>meshes/fximu3e.stl</uri>
            <scale>0.001 0.001 0.001</scale>
          </mesh>
        </geometry>
      </collision>
      <visual name="imu_link_visual">
        <pose>0 0 0 0 0 0</pose>
        <geometry>
          <mesh>
            <uri>meshes/fximu3e.dae</uri>
            <scale>1 1 1</scale>
          </mesh>
        </geometry>
      </visual>
      <sensor name="imu_sensor" type="imu">
            <always_on>1</always_on>
            <update_rate>10</update_rate>
            <visualize>true</visualize>
            <topic>/imu</topic>
      </sensor>
      <gravity>1</gravity>
      <kinematic>0</kinematic>
    </link>

    <joint name="battery_joint" type="fixed">
      <parent>base_link</parent>
      <child>battery_link</child>
    </joint>
    <link name="battery_link">
      <pose>-0.07183 0 0.04285 0 0 0</pose>
      <inertial>
        <pose>0 0 0 0 0 0</pose>
        <inertia>
          <ixx>0.00087161</ixx>
          <ixy>0.0</ixy>
          <ixz>0.0</ixz>
          <iyy>0.000221404</iyy>
          <iyz>0.0</iyz>
          <izz>0.001038422</izz>
        </inertia>
        <mass>0.43</mass>
      </inertial>
      <collision name='battery_link_collision'>
        <pose>0 0 0 0 0 0</pose>
        <geometry>
          <box>
            <size>0.0736 0.1535 0.0276</size>
          </box>
        </geometry>
      </collision>
      <visual name="battery_link_visual">
        <pose>0 0 0 0 0 0</pose>
        <geometry>
          <box>
            <size>0.0736 0.1535 0.0276</size>
          </box>
        </geometry>
        <material>
          <script>
            <uri>file://media/materials/scripts/gazebo.material</uri>
            <name>Gazebo/Black</name>
          </script>
        </material>
      </visual>
      <gravity>1</gravity>
      <kinematic>0</kinematic>
    </link>

  </model>
</sdf>